exceptionHandlings = [
    {
        "question": "What is exception handling in Python?",
        "options": ["A way to ignore errors", "A method to handle runtime errors", "A debugging technique", "A function to fix errors"],
        "answer": "A method to handle runtime errors"
    },
    {
        "question": "Which keyword is used to catch exceptions in Python?",
        "options": ["catch", "handle", "except", "error"],
        "answer": "except"
    },
    {
        "question": "Which keyword is used to define a block of code that may raise an exception?",
        "options": ["try", "catch", "raise", "finally"],
        "answer": "try"
    },
    {
        "question": "What is the purpose of the `finally` block in exception handling?",
        "options": ["To catch errors", "To execute code regardless of an exception", "To stop execution", "To log errors"],
        "answer": "To execute code regardless of an exception"
    },
    {
        "question": "Which built-in exception is raised when you try to divide by zero?",
        "options": ["ZeroDivisionError", "ArithmeticError", "ValueError", "TypeError"],
        "answer": "ZeroDivisionError"
    },
    {
        "question": "Which built-in exception is raised when a function receives an argument of the wrong type?",
        "options": ["ValueError", "TypeError", "KeyError", "IndexError"],
        "answer": "TypeError"
    },
    {
        "question": "Which exception is raised when a key is not found in a dictionary?",
        "options": ["IndexError", "KeyError", "TypeError", "ValueError"],
        "answer": "KeyError"
    },
    {
        "question": "Which exception is raised when accessing an invalid index in a list?",
        "options": ["IndexError", "KeyError", "TypeError", "NameError"],
        "answer": "IndexError"
    },
    {
        "question": "How do you manually raise an exception in Python?",
        "options": ["throw", "raise", "error", "except"],
        "answer": "raise"
    },
    {
        "question": "What is the purpose of the `else` block in exception handling?",
        "options": ["To run if no exceptions occur", "To catch exceptions", "To raise an exception", "To execute always"],
        "answer": "To run if no exceptions occur"
    },
    {
        "question": "Which of the following exceptions is raised when trying to open a non-existent file?",
        "options": ["FileNotFoundError", "IOError", "OSError", "NameError"],
        "answer": "FileNotFoundError"
    },
    {
        "question": "Which built-in exception is raised when a function is called with the wrong number of arguments?",
        "options": ["TypeError", "ValueError", "IndexError", "AttributeError"],
        "answer": "TypeError"
    },
    {
        "question": "Which exception is raised for invalid operations on numeric data types?",
        "options": ["TypeError", "ValueError", "ArithmeticError", "IndexError"],
        "answer": "ValueError"
    },
    {
        "question": "What is the best way to handle multiple exceptions in one `except` block?",
        "options": ["Using multiple `except` blocks", "Using a tuple of exception types", "Using nested try-except", "Using multiple `finally` blocks"],
        "answer": "Using a tuple of exception types"
    },
    {
        "question": "Which exception is raised when trying to access an undefined variable?",
        "options": ["NameError", "KeyError", "IndexError", "TypeError"],
        "answer": "NameError"
    },
    {
        "question": "What does the `try` block do?",
        "options": ["Handles exceptions", "Defines code that may raise exceptions", "Executes always", "Ignores errors"],
        "answer": "Defines code that may raise exceptions"
    },
    {
        "question": "What is the output of `print(1/0)`?",
        "options": ["0", "1", "ZeroDivisionError", "None"],
        "answer": "ZeroDivisionError"
    },
    {
        "question": "Which exception is raised when attempting to open a file without permission?",
        "options": ["PermissionError", "FileNotFoundError", "OSError", "TypeError"],
        "answer": "PermissionError"
    },
    {
        "question": "Which keyword is used to handle exceptions?",
        "options": ["catch", "try", "except", "handle"],
        "answer": "except"
    },
    {
        "question": "What happens if an exception is not handled?",
        "options": ["The program continues", "The program crashes", "The error is ignored", "The exception is logged"],
        "answer": "The program crashes"
    },
    {
        "question": "Can you have multiple `except` blocks for a single `try` block?",
        "options": ["Yes", "No"],
        "answer": "Yes"
    },
    {
        "question": "Which of the following will not raise an exception?",
        "options": ["1/0", "int('abc')", "open('nonexistent.txt')", "print(10)"],
        "answer": "print(10)"
    },
    {
        "question": "What is the correct syntax for catching multiple exceptions?",
        "options": ["except (TypeError, ValueError):", "except TypeError or ValueError:", "except TypeError, ValueError:", "except [TypeError, ValueError]:"],
        "answer": "except (TypeError, ValueError):"
    },
    {
        "question": "What type of error does `int('xyz')` raise?",
        "options": ["TypeError", "ValueError", "SyntaxError", "IndexError"],
        "answer": "ValueError"
    },
    {
        "question": "Which statement about the `finally` block is true?",
        "options": ["It runs only when an exception occurs", "It runs only if no exception occurs", "It always runs", "It never runs"],
        "answer": "It always runs"
    },
    {
        "question": "Can a function handle exceptions internally?",
        "options": ["Yes", "No"],
        "answer": "Yes"
    },
    {
        "question": "What will happen if an exception is raised inside a `finally` block?",
        "options": ["It is ignored", "It terminates execution", "It is handled by another except block", "The program continues"],
        "answer": "It terminates execution"
    },
    {
        "question": "Which error occurs if you try to convert a string 'abc' to an integer using `int()`?",
        "options": ["TypeError", "ValueError", "SyntaxError", "IndexError"],
        "answer": "ValueError"
    },
    {
        "question": "Which function is used to print an error message in a custom exception?",
        "options": ["print()", "raise()", "str()", "__str__()"],
        "answer": "__str__()"
    },
    {
        "question": "Which built-in exception occurs when trying to import a non-existent module?",
        "options": ["ImportError", "ModuleNotFoundError", "KeyError", "ValueError"],
        "answer": "ModuleNotFoundError"
    }
]